<?xml version="1.0"?>
<robot name="student_fwd_vehicle">
  <material name="wizard_chassis_blue">
    <color rgba="0.2784314 0.64705884 1 1" />
  </material><material name="hidden_helper">
    <color rgba="0 0 0 0" />
  </material><material name="wheel_black">
    <color rgba="0.06 0.06 0.06 1" />
  </material><link name="base_link">
    <visual>
      <origin xyz="0 0 0" rpy="0 0 0" />
      <geometry>
        <box size="4 2 1" />
      </geometry><material name="wizard_chassis_blue" />
    </visual><collision>
      <origin xyz="0 0 0" rpy="0 0 0" />
      <geometry>
        <box size="4 2 1" />
      </geometry>
    </collision><inertial>
      <origin xyz="0 0 0" rpy="0 0 0" />
      <mass value="1800" />
      <inertia ixx="750" ixy="0" ixz="0" iyy="2550" iyz="0" izz="3000" />
    </inertial>
  </link><link name="front_left_suspension_link">
    <visual>
      <origin xyz="0 0 0" rpy="0 0 0" />
      <geometry>
        <box size="0.08 0.05 0.175" />
      </geometry><material name="hidden_helper" />
    </visual><inertial>
      <origin xyz="0 0 0" rpy="0 0 0" />
      <mass value="6" />
      <inertia ixx="0.0165625" ixy="0" ixz="0" iyy="0.0185125" iyz="0" izz="0.00445" />
    </inertial>
  </link><joint name="front_left_suspension_joint" type="prismatic">
    <origin xyz="1.3 1 -0.325" rpy="0 0 0" />
    <parent link="base_link" />
    <child link="front_left_suspension_link" />
    <axis xyz="0 0 1" />
    <limit lower="-0.175" upper="0.175" effort="15000" velocity="3" />
    <dynamics damping="2200" friction="120" />
  </joint><link name="front_left_steer_link">
    <visual>
      <origin xyz="0 0 0" rpy="0 0 0" />
      <geometry>
        <sphere radius="0.045" />
      </geometry><material name="hidden_helper" />
    </visual><inertial>
      <origin xyz="0 0 0" rpy="0 0 0" />
      <mass value="3" />
      <inertia ixx="0.00405" ixy="0" ixz="0" iyy="0.00405" iyz="0" izz="0.00405" />
    </inertial>
  </link><joint name="front_left_steer_joint" type="revolute">
    <origin xyz="0 0 -0.0875" rpy="0 0 0" />
    <parent link="front_left_suspension_link" />
    <child link="front_left_steer_link" />
    <axis xyz="0 0 1" />
    <limit lower="-0.558505361" upper="0.558505361" effort="1200" velocity="4" />
    <dynamics damping="25" friction="1" />
  </joint><link name="front_left_wheel_link">
    <visual>
      <origin xyz="0 0 0" rpy="1.57079633 0 0" />
      <geometry>
        <cylinder radius="0.35" length="0.15" />
      </geometry><material name="wheel_black" />
    </visual><collision>
      <origin xyz="0 0 0" rpy="1.57079633 0 0" />
      <geometry>
        <cylinder radius="0.35" length="0.15" />
      </geometry>
    </collision><inertial>
      <origin xyz="0 0 0" rpy="0 0 0" />
      <mass value="20" />
      <inertia ixx="0.65" ixy="0" ixz="0" iyy="1.225" iyz="0" izz="0.65" />
    </inertial>
  </link><joint name="front_left_wheel_joint" type="continuous">
    <origin xyz="0 0 0" rpy="0 0 0" />
    <parent link="front_left_steer_link" />
    <child link="front_left_wheel_link" />
    <axis xyz="0 1 0" />
    <limit effort="4000" velocity="400" />
    <dynamics damping="0.25" friction="0" />
  </joint><link name="front_right_suspension_link">
    <visual>
      <origin xyz="0 0 0" rpy="0 0 0" />
      <geometry>
        <box size="0.08 0.05 0.175" />
      </geometry><material name="hidden_helper" />
    </visual><inertial>
      <origin xyz="0 0 0" rpy="0 0 0" />
      <mass value="6" />
      <inertia ixx="0.0165625" ixy="0" ixz="0" iyy="0.0185125" iyz="0" izz="0.00445" />
    </inertial>
  </link><joint name="front_right_suspension_joint" type="prismatic">
    <origin xyz="1.3 -1 -0.325" rpy="0 0 0" />
    <parent link="base_link" />
    <child link="front_right_suspension_link" />
    <axis xyz="0 0 1" />
    <limit lower="-0.175" upper="0.175" effort="15000" velocity="3" />
    <dynamics damping="2200" friction="120" />
  </joint><link name="front_right_steer_link">
    <visual>
      <origin xyz="0 0 0" rpy="0 0 0" />
      <geometry>
        <sphere radius="0.045" />
      </geometry><material name="hidden_helper" />
    </visual><inertial>
      <origin xyz="0 0 0" rpy="0 0 0" />
      <mass value="3" />
      <inertia ixx="0.00405" ixy="0" ixz="0" iyy="0.00405" iyz="0" izz="0.00405" />
    </inertial>
  </link><joint name="front_right_steer_joint" type="revolute">
    <origin xyz="0 0 -0.0875" rpy="0 0 0" />
    <parent link="front_right_suspension_link" />
    <child link="front_right_steer_link" />
    <axis xyz="0 0 1" />
    <limit lower="-0.558505361" upper="0.558505361" effort="1200" velocity="4" />
    <dynamics damping="25" friction="1" />
  </joint><link name="front_right_wheel_link">
    <visual>
      <origin xyz="0 0 0" rpy="1.57079633 0 0" />
      <geometry>
        <cylinder radius="0.35" length="0.15" />
      </geometry><material name="wheel_black" />
    </visual><collision>
      <origin xyz="0 0 0" rpy="1.57079633 0 0" />
      <geometry>
        <cylinder radius="0.35" length="0.15" />
      </geometry>
    </collision><inertial>
      <origin xyz="0 0 0" rpy="0 0 0" />
      <mass value="20" />
      <inertia ixx="0.65" ixy="0" ixz="0" iyy="1.225" iyz="0" izz="0.65" />
    </inertial>
  </link><joint name="front_right_wheel_joint" type="continuous">
    <origin xyz="0 0 0" rpy="0 0 0" />
    <parent link="front_right_steer_link" />
    <child link="front_right_wheel_link" />
    <axis xyz="0 1 0" />
    <limit effort="4000" velocity="400" />
    <dynamics damping="0.25" friction="0" />
  </joint><link name="rear_left_suspension_link">
    <visual>
      <origin xyz="0 0 0" rpy="0 0 0" />
      <geometry>
        <box size="0.08 0.05 0.175" />
      </geometry><material name="hidden_helper" />
    </visual><inertial>
      <origin xyz="0 0 0" rpy="0 0 0" />
      <mass value="6" />
      <inertia ixx="0.0165625" ixy="0" ixz="0" iyy="0.0185125" iyz="0" izz="0.00445" />
    </inertial>
  </link><joint name="rear_left_suspension_joint" type="prismatic">
    <origin xyz="-1.3 1 -0.325" rpy="0 0 0" />
    <parent link="base_link" />
    <child link="rear_left_suspension_link" />
    <axis xyz="0 0 1" />
    <limit lower="-0.175" upper="0.175" effort="15000" velocity="3" />
    <dynamics damping="2200" friction="120" />
  </joint><link name="rear_left_wheel_link">
    <visual>
      <origin xyz="0 0 0" rpy="1.57079633 0 0" />
      <geometry>
        <cylinder radius="0.35" length="0.15" />
      </geometry><material name="wheel_black" />
    </visual><collision>
      <origin xyz="0 0 0" rpy="1.57079633 0 0" />
      <geometry>
        <cylinder radius="0.35" length="0.15" />
      </geometry>
    </collision><inertial>
      <origin xyz="0 0 0" rpy="0 0 0" />
      <mass value="20" />
      <inertia ixx="0.65" ixy="0" ixz="0" iyy="1.225" iyz="0" izz="0.65" />
    </inertial>
  </link><joint name="rear_left_wheel_joint" type="continuous">
    <origin xyz="0 0 -0.0875" rpy="0 0 0" />
    <parent link="rear_left_suspension_link" />
    <child link="rear_left_wheel_link" />
    <axis xyz="0 1 0" />
    <limit effort="4000" velocity="400" />
    <dynamics damping="0.25" friction="0" />
  </joint><link name="rear_right_suspension_link">
    <visual>
      <origin xyz="0 0 0" rpy="0 0 0" />
      <geometry>
        <box size="0.08 0.05 0.175" />
      </geometry><material name="hidden_helper" />
    </visual><inertial>
      <origin xyz="0 0 0" rpy="0 0 0" />
      <mass value="6" />
      <inertia ixx="0.0165625" ixy="0" ixz="0" iyy="0.0185125" iyz="0" izz="0.00445" />
    </inertial>
  </link><joint name="rear_right_suspension_joint" type="prismatic">
    <origin xyz="-1.3 -1 -0.325" rpy="0 0 0" />
    <parent link="base_link" />
    <child link="rear_right_suspension_link" />
    <axis xyz="0 0 1" />
    <limit lower="-0.175" upper="0.175" effort="15000" velocity="3" />
    <dynamics damping="2200" friction="120" />
  </joint><link name="rear_right_wheel_link">
    <visual>
      <origin xyz="0 0 0" rpy="1.57079633 0 0" />
      <geometry>
        <cylinder radius="0.35" length="0.15" />
      </geometry><material name="wheel_black" />
    </visual><collision>
      <origin xyz="0 0 0" rpy="1.57079633 0 0" />
      <geometry>
        <cylinder radius="0.35" length="0.15" />
      </geometry>
    </collision><inertial>
      <origin xyz="0 0 0" rpy="0 0 0" />
      <mass value="20" />
      <inertia ixx="0.65" ixy="0" ixz="0" iyy="1.225" iyz="0" izz="0.65" />
    </inertial>
  </link><joint name="rear_right_wheel_joint" type="continuous">
    <origin xyz="0 0 -0.0875" rpy="0 0 0" />
    <parent link="rear_right_suspension_link" />
    <child link="rear_right_wheel_link" />
    <axis xyz="0 1 0" />
    <limit effort="4000" velocity="400" />
    <dynamics damping="0.25" friction="0" />
  </joint>
</robot>
